<?xml version="1.0" encoding="utf-8"?>
<!-- This URDF was automatically created by SolidWorks to URDF Exporter! Originally created by Stephen Brawner (brawner@gmail.com) 
     Commit Version: 1.5.0-0-g9aa0fdb  Build Version: 1.5.7004.21443
     For more information, please see http://wiki.ros.org/sw_urdf_exporter -->
<robot
  name="aragog_urdf">
  <link
    name="base_link">
    <inertial>
      <origin
        xyz="-5.45551002226673E-17 1.34529368211767E-18 0.00531609098066728"
        rpy="0 0 0" />
      <mass
        value="3.32238920691748" />
      <inertia
        ixx="0.00811436673472104"
        ixy="-4.30296161001022E-19"
        ixz="-1.84347865210351E-19"
        iyy="0.0180496934141333"
        iyz="1.03429844178161E-19"
        izz="0.0187962771271448" />
    </inertial>
    <visual>
      <origin
        xyz="0 0 0"
        rpy="0 0 0" />
      <geometry>
        <mesh
          filename="package://aragog_urdf/meshes/base_link.STL" />
      </geometry>
      <material
        name="blue">
        <color
          rgba="0.0392156862745098 0.490196078431373 0.709803921568627 1" />
      </material>
    </visual>
    <collision>
      <origin
        xyz="0 0 0"
        rpy="0 0 0" />
      <geometry>
        <mesh
          filename="package://aragog_urdf/meshes/base_link.STL" />
      </geometry>
    </collision>
  </link>
  <link
    name="Front_module">
    <inertial>
      <origin
        xyz="-0.0497172643592256 6.86395702539619E-17 4.85722573273506E-17"
        rpy="0 0 0" />
      <mass
        value="0.376403583442598" />
      <inertia
        ixx="0.00122457497789135"
        ixy="2.18535755074101E-19"
        ixz="-1.53202230184357E-20"
        iyy="0.000273263744958828"
        iyz="1.62050311598109E-19"
        izz="0.00143195312999982" />
    </inertial>
    <visual>
      <origin
        xyz="0 0 0"
        rpy="0 0 0" />
      <geometry>
        <mesh
          filename="package://aragog_urdf/meshes/Front_module.STL" />
      </geometry>
      <material
        name="">
        <color
          rgba="1 0 0 1" />
      </material>
    </visual>
    <collision>
      <origin
        xyz="0 0 0"
        rpy="0 0 0" />
      <geometry>
        <mesh
          filename="package://aragog_urdf/meshes/Front_module.STL" />
      </geometry>
    </collision>
  </link>
  <joint
    name="FM_joint"
    type="revolute">
    <origin
      xyz="-0.115 0 0.042"
      rpy="0 0 0" />
    <parent
      link="base_link" />
    <child
      link="Front_module" />
    <axis
      xyz="0 1 0" />
    <limit
      lower="-3.14"
      upper="3.14"
      effort="0"
      velocity="0" />
    <safety_controller
      k_velocity="0" />
  </joint>
  <link
    name="FLA">
    <inertial>
      <origin
        xyz="-0.0278699932792812 -0.0349280778773409 1.06796636395456E-08"
        rpy="0 0 0" />
      <mass
        value="0.295029754126894" />
      <inertia
        ixx="0.000309535633973418"
        ixy="-5.80478947344437E-11"
        ixz="1.43627711665173E-11"
        iyy="0.000169221307104425"
        iyz="-1.00079234323134E-11"
        izz="0.000390392374765467" />
    </inertial>
    <visual>
      <origin
        xyz="0 0 0"
        rpy="0 0 0" />
      <geometry>
        <mesh
          filename="package://aragog_urdf/meshes/FLA.STL" />
      </geometry>
      <material
        name="">
        <color
          rgba="0 0 1 1" />
      </material>
    </visual>
    <collision>
      <origin
        xyz="0 0 0"
        rpy="0 0 0" />
      <geometry>
        <mesh
          filename="package://aragog_urdf/meshes/FLA.STL" />
      </geometry>
    </collision>
  </link>
  <joint
    name="FLA_joint"
    type="revolute">
    <origin
      xyz="0 -0.11275 0"
      rpy="1.5707963267949 0 0" />
    <parent
      link="Front_module" />
    <child
      link="FLA" />
    <axis
      xyz="1 0 0" />
    <limit
      lower="-3.14"
      upper="3.14"
      effort="0"
      velocity="0" />
    <safety_controller
      k_velocity="0" />
  </joint>
  <link
    name="FLH">
    <inertial>
      <origin
        xyz="2.12419992786303E-05 -0.0411680002134707 0.00875381508802056"
        rpy="0 0 0" />
      <mass
        value="0.08" />
      <inertia
        ixx="0.000181237968458974"
        ixy="8.77373051205217E-08"
        ixz="1.54511395588275E-08"
        iyy="2.6110291682208E-05"
        iyz="-2.67712058288425E-06"
        izz="0.000202371902016721" />
    </inertial>
    <visual>
      <origin
        xyz="0 0 0"
        rpy="0 0 0" />
      <geometry>
        <mesh
          filename="package://aragog_urdf/meshes/FLH.STL" />
      </geometry>
      <material
        name="">
        <color
          rgba="0 0.937254901960784 0.125490196078431 1" />
      </material>
    </visual>
    <collision>
      <origin
        xyz="0 0 0"
        rpy="0 0 0" />
      <geometry>
        <mesh
          filename="package://aragog_urdf/meshes/FLH.STL" />
      </geometry>
    </collision>
  </link>
  <joint
    name="FLH_joint"
    type="revolute">
    <origin
      xyz="-0.0278699999999998 -0.0830127664691537 0.021"
      rpy="0 0 1.5707963267949" />
    <parent
      link="FLA" />
    <child
      link="FLH" />
    <axis
      xyz="0 0 -1" />
    <limit
      lower="-3.14"
      upper="3.14"
      effort="0"
      velocity="0" />
    <safety_controller
      k_velocity="0" />
  </joint>
  <link
    name="FLK">
    <inertial>
      <origin
        xyz="3.6644108067363E-08 0.100111301705053 0.00305521968276382"
        rpy="0 0 0" />
      <mass
        value="0.0167134646126867" />
      <inertia
        ixx="0.00010038228684169"
        ixy="3.71456275042034E-13"
        ixz="-2.21427736998955E-12"
        iyy="2.07821056706645E-06"
        iyz="3.82445657532547E-07"
        izz="0.000102234595439406" />
    </inertial>
    <visual>
      <origin
        xyz="0 0 0"
        rpy="0 0 0" />
      <geometry>
        <mesh
          filename="package://aragog_urdf/meshes/FLK.STL" />
      </geometry>
      <material
        name="">
        <color
          rgba="1 1 0 1" />
      </material>
    </visual>
    <collision>
      <origin
        xyz="0 0 0"
        rpy="0 0 0" />
      <geometry>
        <mesh
          filename="package://aragog_urdf/meshes/FLK.STL" />
      </geometry>
    </collision>
  </link>
  <joint
    name="FLK_joint"
    type="revolute">
    <origin
      xyz="0 -0.15 0.02"
      rpy="0 0 3.14159265358979" />
    <parent
      link="FLH" />
    <child
      link="FLK" />
    <axis
      xyz="0 0 1" />
    <limit
      lower="-3.14"
      upper="3.14"
      effort="0"
      velocity="0" />
    <safety_controller
      k_velocity="0" />
  </joint>
  <link
    name="FRA">
    <inertial>
      <origin
        xyz="-0.0278699932792812 -0.0349280778773409 1.06796637089346E-08"
        rpy="0 0 0" />
      <mass
        value="0.295029754126894" />
      <inertia
        ixx="0.000309535633973418"
        ixy="-5.80478947169105E-11"
        ixz="1.43627711554638E-11"
        iyy="0.000169221307104425"
        iyz="-1.00079234263126E-11"
        izz="0.000390392374765467" />
    </inertial>
    <visual>
      <origin
        xyz="0 0 0"
        rpy="0 0 0" />
      <geometry>
        <mesh
          filename="package://aragog_urdf/meshes/FRA.STL" />
      </geometry>
      <material
        name="">
        <color
          rgba="0 0 1 1" />
      </material>
    </visual>
    <collision>
      <origin
        xyz="0 0 0"
        rpy="0 0 0" />
      <geometry>
        <mesh
          filename="package://aragog_urdf/meshes/FRA.STL" />
      </geometry>
    </collision>
  </link>
  <joint
    name="FRA_joint"
    type="revolute">
    <origin
      xyz="0 0.11275 0"
      rpy="1.5707963267949 0 0" />
    <parent
      link="Front_module" />
    <child
      link="FRA" />
    <axis
      xyz="1 0 0" />
    <limit
      lower="-3.14"
      upper="3.14"
      effort="0"
      velocity="0" />
    <safety_controller
      k_velocity="0" />
  </joint>
  <link
    name="FRH">
    <inertial>
      <origin
        xyz="-2.12419992784707E-05 -0.0411680002134707 -0.00875381508802756"
        rpy="0 0 0" />
      <mass
        value="0.08" />
      <inertia
        ixx="0.000181237968458974"
        ixy="-8.77373051204196E-08"
        ixz="1.54511395588163E-08"
        iyy="2.6110291682208E-05"
        iyz="2.67712058288413E-06"
        izz="0.000202371902016721" />
    </inertial>
    <visual>
      <origin
        xyz="0 0 0"
        rpy="0 0 0" />
      <geometry>
        <mesh
          filename="package://aragog_urdf/meshes/FRH.STL" />
      </geometry>
      <material
        name="">
        <color
          rgba="0 0.937254901960784 0.125490196078431 1" />
      </material>
    </visual>
    <collision>
      <origin
        xyz="0 0 0"
        rpy="0 0 0" />
      <geometry>
        <mesh
          filename="package://aragog_urdf/meshes/FRH.STL" />
      </geometry>
    </collision>
  </link>
  <joint
    name="FRH_joint"
    type="revolute">
    <origin
      xyz="-0.0278699999999998 -0.0830127664691537 -0.021"
      rpy="0 0 1.5707963267949" />
    <parent
      link="FRA" />
    <child
      link="FRH" />
    <axis
      xyz="0 0 -1" />
    <limit
      lower="-3.14"
      upper="3.14"
      effort="0"
      velocity="0" />
    <safety_controller
      k_velocity="0" />
  </joint>
  <link
    name="FRK">
    <inertial>
      <origin
        xyz="-3.66441086710467E-08 0.100111301705053 -0.00305521968276384"
        rpy="0 0 0" />
      <mass
        value="0.0167134646126866" />
      <inertia
        ixx="0.00010038228684169"
        ixy="-3.7145593913377E-13"
        ixz="-2.21427736900092E-12"
        iyy="2.07821056706645E-06"
        iyz="-3.82445657532456E-07"
        izz="0.000102234595439406" />
    </inertial>
    <visual>
      <origin
        xyz="0 0 0"
        rpy="0 0 0" />
      <geometry>
        <mesh
          filename="package://aragog_urdf/meshes/FRK.STL" />
      </geometry>
      <material
        name="">
        <color
          rgba="1 1 0 1" />
      </material>
    </visual>
    <collision>
      <origin
        xyz="0 0 0"
        rpy="0 0 0" />
      <geometry>
        <mesh
          filename="package://aragog_urdf/meshes/FRK.STL" />
      </geometry>
    </collision>
  </link>
  <joint
    name="FRK_joint"
    type="revolute">
    <origin
      xyz="0 -0.15 -0.0200000000000002"
      rpy="0 0 3.14159265358979" />
    <parent
      link="FRH" />
    <child
      link="FRK" />
    <axis
      xyz="0 0 1" />
    <limit
      lower="-3.14"
      upper="3.14"
      effort="0"
      velocity="0" />
    <safety_controller
      k_velocity="0" />
  </joint>
  <link
    name="Back_module">
    <inertial>
      <origin
        xyz="0.0497172643592256 7.87660632798329E-17 0"
        rpy="0 0 0" />
      <mass
        value="0.376403583442599" />
      <inertia
        ixx="0.00122457497789136"
        ixy="-4.00655797350407E-19"
        ixz="-1.36787983258632E-20"
        iyy="0.000273263744958829"
        iyz="2.59747855753548E-20"
        izz="0.00143195312999983" />
    </inertial>
    <visual>
      <origin
        xyz="0 0 0"
        rpy="0 0 0" />
      <geometry>
        <mesh
          filename="package://aragog_urdf/meshes/Back_module.STL" />
      </geometry>
      <material
        name="">
        <color
          rgba="1 0.168627450980392 0.168627450980392 1" />
      </material>
    </visual>
    <collision>
      <origin
        xyz="0 0 0"
        rpy="0 0 0" />
      <geometry>
        <mesh
          filename="package://aragog_urdf/meshes/Back_module.STL" />
      </geometry>
    </collision>
  </link>
  <joint
    name="BM_joint"
    type="revolute">
    <origin
      xyz="0.115 0 0.042"
      rpy="0 0 0" />
    <parent
      link="base_link" />
    <child
      link="Back_module" />
    <axis
      xyz="0 1 0" />
    <limit
      lower="-3.14"
      upper="3.14"
      effort="0"
      velocity="0" />
    <safety_controller
      k_velocity="0" />
  </joint>
  <link
    name="BLA">
    <inertial>
      <origin
        xyz="0.0278700067207168 -0.0349280778773408 1.06796638615902E-08"
        rpy="0 0 0" />
      <mass
        value="0.295029754126894" />
      <inertia
        ixx="0.000309535633973418"
        ixy="-5.80478947641281E-11"
        ixz="1.43627711663126E-11"
        iyy="0.000169221307104425"
        iyz="-1.00079234311191E-11"
        izz="0.000390392374765467" />
    </inertial>
    <visual>
      <origin
        xyz="0 0 0"
        rpy="0 0 0" />
      <geometry>
        <mesh
          filename="package://aragog_urdf/meshes/BLA.STL" />
      </geometry>
      <material
        name="">
        <color
          rgba="0 0 1 1" />
      </material>
    </visual>
    <collision>
      <origin
        xyz="0 0 0"
        rpy="0 0 0" />
      <geometry>
        <mesh
          filename="package://aragog_urdf/meshes/BLA.STL" />
      </geometry>
    </collision>
  </link>
  <joint
    name="BLA_joint"
    type="revolute">
    <origin
      xyz="0 -0.11275 0"
      rpy="1.5707963267949 0 0" />
    <parent
      link="Back_module" />
    <child
      link="BLA" />
    <axis
      xyz="1 0 0" />
    <limit
      lower="-3.14"
      upper="3.14"
      effort="0"
      velocity="0" />
    <safety_controller
      k_velocity="0" />
  </joint>
  <link
    name="BLH">
    <inertial>
      <origin
        xyz="2.12440008776765E-05 -0.041168005929885 0.00875381452700574"
        rpy="0 0 0" />
      <mass
        value="0.08" />
      <inertia
        ixx="0.000181238000146866"
        ixy="8.77467255772021E-08"
        ixz="1.54521079081354E-08"
        iyy="2.61102953867185E-05"
        iyz="-2.67712322281538E-06"
        izz="0.000202371936879135" />
    </inertial>
    <visual>
      <origin
        xyz="0 0 0"
        rpy="0 0 0" />
      <geometry>
        <mesh
          filename="package://aragog_urdf/meshes/BLH.STL" />
      </geometry>
      <material
        name="">
        <color
          rgba="0 0.937254901960784 0.125490196078431 1" />
      </material>
    </visual>
    <collision>
      <origin
        xyz="0 0 0"
        rpy="0 0 0" />
      <geometry>
        <mesh
          filename="package://aragog_urdf/meshes/BLH.STL" />
      </geometry>
    </collision>
  </link>
  <joint
    name="BLH_joint"
    type="revolute">
    <origin
      xyz="0.02787 -0.083013 0.021"
      rpy="0 0 1.5708" />
    <parent
      link="BLA" />
    <child
      link="BLH" />
    <axis
      xyz="0 0 -1" />
    <limit
      lower="-3.14"
      upper="3.14"
      effort="0"
      velocity="0" />
    <safety_controller
      k_velocity="0" />
  </joint>
  <link
    name="BLK">
    <inertial>
      <origin
        xyz="3.6644E-08 0.10011 0.0030552"
        rpy="0 0 0" />
      <mass
        value="0.016713" />
      <inertia
        ixx="0.00010038"
        ixy="3.7146E-13"
        ixz="-2.2143E-12"
        iyy="2.0782E-06"
        iyz="3.8245E-07"
        izz="0.00010223" />
    </inertial>
    <visual>
      <origin
        xyz="0 0 0"
        rpy="0 0 0" />
      <geometry>
        <mesh
          filename="package://aragog_urdf/meshes/BLK.STL" />
      </geometry>
      <material
        name="">
        <color
          rgba="1 1 0 1" />
      </material>
    </visual>
    <collision>
      <origin
        xyz="0 0 0"
        rpy="0 0 0" />
      <geometry>
        <mesh
          filename="package://aragog_urdf/meshes/BLK.STL" />
      </geometry>
    </collision>
  </link>
  <joint
    name="BLK_joint"
    type="revolute">
    <origin
      xyz="0 -0.149999999999998 0.02"
      rpy="0 0 3.14159265358978" />
    <parent
      link="BLH" />
    <child
      link="BLK" />
    <axis
      xyz="0 0 1" />
    <limit
      lower="-3.14"
      upper="3.14"
      effort="0"
      velocity="0" />
    <safety_controller
      k_velocity="0" />
  </joint>
  <link
    name="BRA">
    <inertial>
      <origin
        xyz="0.0278700067207183 -0.0349280778773409 1.0679663681179E-08"
        rpy="0 0 0" />
      <mass
        value="0.295029754126894" />
      <inertia
        ixx="0.000309535633973418"
        ixy="-5.80478947917704E-11"
        ixz="1.43627711660787E-11"
        iyy="0.000169221307104425"
        iyz="-1.00079234338835E-11"
        izz="0.000390392374765467" />
    </inertial>
    <visual>
      <origin
        xyz="0 0 0"
        rpy="0 0 0" />
      <geometry>
        <mesh
          filename="package://aragog_urdf/meshes/BRA.STL" />
      </geometry>
      <material
        name="">
        <color
          rgba="0 0 1 1" />
      </material>
    </visual>
    <collision>
      <origin
        xyz="0 0 0"
        rpy="0 0 0" />
      <geometry>
        <mesh
          filename="package://aragog_urdf/meshes/BRA.STL" />
      </geometry>
    </collision>
  </link>
  <joint
    name="BRA_joint"
    type="revolute">
    <origin
      xyz="0 0.11275 0"
      rpy="1.5707963267949 0 0" />
    <parent
      link="Back_module" />
    <child
      link="BRA" />
    <axis
      xyz="1 0 0" />
    <limit
      lower="-3.14"
      upper="3.14"
      effort="0"
      velocity="0" />
    <safety_controller
      k_velocity="0" />
  </joint>
  <link
    name="BRH">
    <inertial>
      <origin
        xyz="-2.12423345357649E-05 -0.0411680011324299 -0.00875381500475839"
        rpy="0 0 0" />
      <mass
        value="0.08" />
      <inertia
        ixx="0.00018123797352175"
        ixy="-8.77388606656854E-08"
        ixz="1.54512891336484E-08"
        iyy="2.61102923072211E-05"
        iyz="2.67712096593016E-06"
        izz="0.000202371907637502" />
    </inertial>
    <visual>
      <origin
        xyz="0 0 0"
        rpy="0 0 0" />
      <geometry>
        <mesh
          filename="package://aragog_urdf/meshes/BRH.STL" />
      </geometry>
      <material
        name="">
        <color
          rgba="0 0.937254901960784 0.125490196078431 1" />
      </material>
    </visual>
    <collision>
      <origin
        xyz="0 0 0"
        rpy="0 0 0" />
      <geometry>
        <mesh
          filename="package://aragog_urdf/meshes/BRH.STL" />
      </geometry>
    </collision>
  </link>
  <joint
    name="BRH_joint"
    type="revolute">
    <origin
      xyz="0.0278699999999998 -0.0830127664691537 -0.0209999999999999"
      rpy="0 0 1.5707963267949" />
    <parent
      link="BRA" />
    <child
      link="BRH" />
    <axis
      xyz="0 0 -1" />
    <limit
      lower="-3.14"
      upper="3.14"
      effort="0"
      velocity="0" />
    <safety_controller
      k_velocity="0" />
  </joint>
  <link
    name="BRK">
    <inertial>
      <origin
        xyz="-3.66441077551127E-08 0.100111301705049 -0.00305521968276057"
        rpy="0 0 0" />
      <mass
        value="0.0167134646126867" />
      <inertia
        ixx="0.000100382286841691"
        ixy="-3.71456575225655E-13"
        ixz="-2.21427737293597E-12"
        iyy="2.07821056706646E-06"
        iyz="-3.82445657532474E-07"
        izz="0.000102234595439407" />
    </inertial>
    <visual>
      <origin
        xyz="0 0 0"
        rpy="0 0 0" />
      <geometry>
        <mesh
          filename="package://aragog_urdf/meshes/BRK.STL" />
      </geometry>
      <material
        name="">
        <color
          rgba="1 1 0 1" />
      </material>
    </visual>
    <collision>
      <origin
        xyz="0 0 0"
        rpy="0 0 0" />
      <geometry>
        <mesh
          filename="package://aragog_urdf/meshes/BRK.STL" />
      </geometry>
    </collision>
  </link>
  <joint
    name="BRK_joint"
    type="revolute">
    <origin
      xyz="0 -0.149999999999997 -0.02"
      rpy="0 0 -3.14159265358979" />
    <parent
      link="BRH" />
    <child
      link="BRK" />
    <axis
      xyz="0 0 1" />
    <limit
      lower="-3.14"
      upper="3.14"
      effort="0"
      velocity="0" />
    <safety_controller
      k_velocity="0" />
  </joint>
</robot>